Workbook

Sheet Preguntas
A1: Preguntas del formulario
A2: Una fila por pregunta, en el orden en que aparecen. Elegí la Sección y después la Subsección (la lista muestra solo las de esa sección). Para agregar: clic derecho en el número de fila → Insertar. Cada sección tiene su color (aunque agregues filas al final, toman el color de su sección). Al subir la planilla, la herramienta agrupa sola por Sección y Subsección.
A3: Ruta JSON: elegila de la lista (sale de tu JSON) y en "Valor en el JSON" vas a ver el dato de ejemplo. Si una ruta tiene [i], la pregunta se repite (ej. varios bienes). Las filas grises son datos ocultos: los completa Namirial.
A5: Sección | B5: Subsección | C5: Pregunta | D5: Tipo | E5: Opciones | F5: Obligatoria | G5: Viene prellenado | H5: Se puede editar | I5: Se muestra si | J5: Ruta JSON | K5: Valor en el JSON | L5: En el PDF va partido en | M5: Reglas / formato | N5: ¿Va? | O5: Notas | P5: ID (no tocar) | Q5: grupo | R5: seccion
A6: Datos del sistema (oculto) | B6: Encabezado | C6: Tipo de Formulario | D6: Dato oculto | G6: Sí | H6: No | J6: encabezado.codigoTipoFormulario | K6: =IF(J6="","",IFERROR(INDEX('JSON del cliente'!$B$5:$B$288,MATCH(J6,'JSON del cliente'!$A$5:$A$288,0)),"no está en el JSON")) -> EQE02 | M6: Valor fijo | N6: Sí | Q6: =1 -> 1 | R6: =IF($A6="","",IFERROR(INDEX(R$5:R5,MATCH($A6,$A$5:$A5,0)),MAX(R$5:R5)+1)) -> 1
A7: Datos del sistema (oculto) | B7: Encabezado | C7: Descripción Tipo Formulario | D7: Dato oculto | G7: Sí | H7: No | J7: encabezado.descripcionTipoFormulario | K7: =IF(J7="","",IFERROR(INDEX('JSON del cliente'!$B$5:$B$288,MATCH(J7,'JSON del cliente'!$A$5:$A$288,0)),"no está en el JSON")) -> Equipo Electrónico Modalidad Adhesión para Equipo Móvil y/o Portátil | M7: Valor fijo | N7: Sí | Q7: =IF(AND($A7=$A6,$B7=$B6),Q6,Q6+1) -> 1 | R7: =IF($A7="","",IFERROR(INDEX(R$5:R6,MATCH($A7,$A$5:$A6,0)),MAX(R$5:R6)+1)) -> 1
A8: Datos del sistema (oculto) | B8: Encabezado | C8: Tipo Trámite | D8: Dato oculto | G8: Sí | H8: No | J8: encabezado.codigoTipoTramite | K8: =IF(J8="","",IFERROR(INDEX('JSON del cliente'!$B$5:$B$288,MATCH(J8,'JSON del cliente'!$A$5:$A$288,0)),"no está en el JSON")) -> Ver catálogo | M8: Viene del sistema | N8: Sí | Q8: =IF(AND($A8=$A7,$B8=$B7),Q7,Q7+1) -> 1 | R8: =IF($A8="","",IFERROR(INDEX(R$5:R7,MATCH($A8,$A$5:$A7,0)),MAX(R$5:R7)+1)) -> 1
A9: Datos del sistema (oculto) | B9: Encabezado | C9: Descripción Tipo Trámite | D9: Dato oculto | G9: Sí | H9: No | J9: encabezado.descripcionTipoTramite | K9: =IF(J9="","",IFERROR(INDEX('JSON del cliente'!$B$5:$B$288,MATCH(J9,'JSON del cliente'!$A$5:$A$288,0)),"no está en el JSON")) -> Ver catálogo | M9: Se calcula | N9: Sí | O9: Del catálogo | Q9: =IF(AND($A9=$A8,$B9=$B8),Q8,Q8+1) -> 1 | R9: =IF($A9="","",IFERROR(INDEX(R$5:R8,MATCH($A9,$A$5:$A8,0)),MAX(R$5:R8)+1)) -> 1
A10: Datos del sistema (oculto) | B10: Encabezado | C10: Identificador Transacción Interno | D10: Dato oculto | G10: Sí | H10: No | J10: encabezado.identificadorTransaccionInterno | K10: =IF(J10="","",IFERROR(INDEX('JSON del cliente'!$B$5:$B$288,MATCH(J10,'JSON del cliente'!$A$5:$A$288,0)),"no está en el JSON")) -> INS_SG_P14_EQE02_I_20260801_A_3_0031018555690 | M10: Viene del sistema | N10: Sí | Q10: =IF(AND($A10=$A9,$B10=$B9),Q9,Q9+1) -> 1 | R10: =IF($A10="","",IFERROR(INDEX(R$5:R9,MATCH($A10,$A$5:$A9,0)),MAX(R$5:R9)+1)) -> 1
A11: Datos del sistema (oculto) | B11: Encabezado | C11: Correo electrónico | D11: Dato oculto | G11: Sí | H11: No | J11: encabezado.correoElectronico | K11: =IF(J11="","",IFERROR(INDEX('JSON del cliente'!$B$5:$B$288,MATCH(J11,'JSON del cliente'!$A$5:$A$288,0)),"no está en el JSON")) -> aleulloaperez@gmail.com | M11: Viene del sistema | N11: Sí | Q11: =IF(AND($A11=$A10,$B11=$B10),Q10,Q10+1) -> 1 | R11: =IF($A11="","",IFERROR(INDEX(R$5:R10,MATCH($A11,$A$5:$A10,0)),MAX(R$5:R10)+1)) -> 1
A12: Datos del sistema (oculto) | B12: Encabezado | C12: Código de Producto | D12: Dato oculto | G12: Sí | H12: No | J12: encabezado.codigoProducto | K12: =IF(J12="","",IFERROR(INDEX('JSON del cliente'!$B$5:$B$288,MATCH(J12,'JSON del cliente'!$A$5:$A$288,0)),"no está en el JSON")) -> 155 | M12: Valor fijo | N12: Sí | Q12: =IF(AND($A12=$A11,$B12=$B11),Q11,Q11+1) -> 1 | R12: =IF($A12="","",IFERROR(INDEX(R$5:R11,MATCH($A12,$A$5:$A11,0)),MAX(R$5:R11)+1)) -> 1
A13: Datos del sistema (oculto) | B13: Encabezado | C13: Descripción Producto | D13: Dato oculto | G13: Sí | H13: No | J13: encabezado.descripcionProducto | K13: =IF(J13="","",IFERROR(INDEX('JSON del cliente'!$B$5:$B$288,MATCH(J13,'JSON del cliente'!$A$5:$A$288,0)),"no está en el JSON")) -> Equipo Electrónico Riesgo Nombrado Equipo Movil y/o Portátil | M13: Valor fijo | N13: Sí | Q13: =IF(AND($A13=$A12,$B13=$B12),Q12,Q12+1) -> 1 | R13: =IF($A13="","",IFERROR(INDEX(R$5:R12,MATCH($A13,$A$5:$A12,0)),MAX(R$5:R12)+1)) -> 1
A14: Datos del sistema (oculto) | B14: Encabezado | C14: Nombre Completo Cliente | D14: Dato oculto | G14: Sí | H14: No | J14: encabezado.nombreCompletoCliente | K14: =IF(J14="","",IFERROR(INDEX('JSON del cliente'!$B$5:$B$288,MATCH(J14,'JSON del cliente'!$A$5:$A$288,0)),"no está en el JSON")) -> Alejandro Ulloa Pérez | M14: Viene del sistema | N14: Sí | Q14: =IF(AND($A14=$A13,$B14=$B13),Q13,Q13+1) -> 1 | R14: =IF($A14="","",IFERROR(INDEX(R$5:R13,MATCH($A14,$A$5:$A13,0)),MAX(R$5:R13)+1)) -> 1
A15: Datos del sistema (oculto) | B15: Encabezado | C15: Identificador Archivo | D15: Dato oculto | G15: Sí | H15: No | J15: encabezado.identificadorArchivo | K15: =IF(J15="","",IFERROR(INDEX('JSON del cliente'!$B$5:$B$288,MATCH(J15,'JSON del cliente'!$A$5:$A$288,0)),"no está en el JSON")) -> idNamirial | M15: Viene del sistema | N15: Sí | Q15: =IF(AND($A15=$A14,$B15=$B14),Q14,Q14+1) -> 1 | R15: =IF($A15="","",IFERROR(INDEX(R$5:R14,MATCH($A15,$A$5:$A14,0)),MAX(R$5:R14)+1)) -> 1
A16: Datos del sistema (oculto) | B16: Personas | C16: Código de Tipo de Persona | D16: Dato oculto | G16: Sí | H16: No | J16: datosFormulario.personas[0].codigoTipo | K16: =IF(J16="","",IFERROR(INDEX('JSON del cliente'!$B$5:$B$288,MATCH(J16,'JSON del cliente'!$A$5:$A$288,0)),"no está en el JSON")) -> ASG | M16: Valor fijo | N16: Sí | O16: ASG = Asegurado | Q16: =IF(AND($A16=$A15,$B16=$B15),Q15,Q15+1) -> 2 | R16: =IF($A16="","",IFERROR(INDEX(R$5:R15,MATCH($A16,$A$5:$A15,0)),MAX(R$5:R15)+1)) -> 1
A17: Datos del sistema (oculto) | B17: Personas | C17: Descripción de Tipo de Persona | D17: Dato oculto | G17: Sí | H17: No | J17: datosFormulario.personas[0].descripcionTipo | K17: =IF(J17="","",IFERROR(INDEX('JSON del cliente'!$B$5:$B$288,MATCH(J17,'JSON del cliente'!$A$5:$A$288,0)),"no está en el JSON")) -> Asegurado | M17: Se calcula | N17: Sí | Q17: =IF(AND($A17=$A16,$B17=$B16),Q16,Q16+1) -> 2 | R17: =IF($A17="","",IFERROR(INDEX(R$5:R16,MATCH($A17,$A$5:$A16,0)),MAX(R$5:R16)+1)) -> 1
A18: Datos del sistema (oculto) | B18: Personas | C18: Descripción Tipo de Identificación | D18: Dato oculto | G18: Sí | H18: No | J18: datosFormulario.personas[0].descripcionTipoIdentificacion | K18: =IF(J18="","",IFERROR(INDEX('JSON del cliente'!$B$5:$B$288,MATCH(J18,'JSON del cliente'!$A$5:$A$288,0)),"no está en el JSON")) -> Física | M18: Se calcula | N18: Sí | Q18: =IF(AND($A18=$A17,$B18=$B17),Q17,Q17+1) -> 2 | R18: =IF($A18="","",IFERROR(INDEX(R$5:R17,MATCH($A18,$A$5:$A17,0)),MAX(R$5:R17)+1)) -> 1
A19: Datos del sistema (oculto) | B19: Personas | C19: Descripción de Estado Civil | D19: Dato oculto | G19: Sí | H19: No | J19: datosFormulario.personas[0].descripcionEstadoCivil | K19: =IF(J19="","",IFERROR(INDEX('JSON del cliente'!$B$5:$B$288,MATCH(J19,'JSON del cliente'!$A$5:$A$288,0)),"no está en el JSON")) -> Casado | M19: Se calcula | N19: Sí | Q19: =IF(AND($A19=$A18,$B19=$B18),Q18,Q18+1) -> 2 | R19: =IF($A19="","",IFERROR(INDEX(R$5:R18,MATCH($A19,$A$5:$A18,0)),MAX(R$5:R18)+1)) -> 1
A20: Datos del sistema (oculto) | B20: Personas | C20: Descripción del Género | D20: Dato oculto | G20: Sí | H20: No | J20: datosFormulario.personas[0].descripcionGenero | K20: =IF(J20="","",IFERROR(INDEX('JSON del cliente'!$B$5:$B$288,MATCH(J20,'JSON del cliente'!$A$5:$A$288,0)),"no está en el JSON")) -> Femenino | M20: Se calcula | N20: Sí | Q20: =IF(AND($A20=$A19,$B20=$B19),Q19,Q19+1) -> 2 | R20: =IF($A20="","",IFERROR(INDEX(R$5:R19,MATCH($A20,$A$5:$A19,0)),MAX(R$5:R19)+1)) -> 1
A21: Datos del sistema (oculto) | B21: Personas | C21: Nombre completo | D21: Dato oculto | G21: Sí | H21: No | J21: datosFormulario.personas[0].nombreCompleto | K21: =IF(J21="","",IFERROR(INDEX('JSON del cliente'!$B$5:$B$288,MATCH(J21,'JSON del cliente'!$A$5:$A$288,0)),"no está en el JSON")) -> Alejandro Ulloa Pérez | M21: Se calcula | N21: Sí | O21: Nombres + apellidos | Q21: =IF(AND($A21=$A20,$B21=$B20),Q20,Q20+1) -> 2 | R21: =IF($A21="","",IFERROR(INDEX(R$5:R20,MATCH($A21,$A$5:$A20,0)),MAX(R$5:R20)+1)) -> 1
A22: Datos del sistema (oculto) | B22: Personas | C22: Edad | D22: Dato oculto | G22: Sí | H22: No | J22: datosFormulario.personas[0].edad | K22: =IF(J22="","",IFERROR(INDEX('JSON del cliente'!$B$5:$B$288,MATCH(J22,'JSON del cliente'!$A$5:$A$288,0)),"no está en el JSON")) -> 47 | M22: Se calcula | N22: Sí | O22: A partir de la fecha de nacimiento | Q22: =IF(AND($A22=$A21,$B22=$B21),Q21,Q21+1) -> 2 | R22: =IF($A22="","",IFERROR(INDEX(R$5:R21,MATCH($A22,$A$5:$A21,0)),MAX(R$5:R21)+1)) -> 1
A23: Datos del sistema (oculto) | B23: Dirección y notificación | C23: Descripción Provincia | D23: Dato oculto | G23: Sí | H23: No | J23: datosFormulario.personas[0].direccion.descripcionProvincia | K23: =IF(J23="","",IFERROR(INDEX('JSON del cliente'!$B$5:$B$288,MATCH(J23,'JSON del cliente'!$A$5:$A$288,0)),"no está en el JSON")) -> San José | M23: Se calcula | N23: Sí | Q23: =IF(AND($A23=$A22,$B23=$B22),Q22,Q22+1) -> 3 | R23: =IF($A23="","",IFERROR(INDEX(R$5:R22,MATCH($A23,$A$5:$A22,0)),MAX(R$5:R22)+1)) -> 1
A24: Datos del sistema (oculto) | B24: Dirección y notificación | C24: Descripción Cantón | D24: Dato oculto | G24: Sí | H24: No | J24: datosFormulario.personas[0].direccion.descripcionCanton | K24: =IF(J24="","",IFERROR(INDEX('JSON del cliente'!$B$5:$B$288,MATCH(J24,'JSON del cliente'!$A$5:$A$288,0)),"no está en el JSON")) -> Tibás | M24: Se calcula | N24: Sí | Q24: =IF(AND($A24=$A23,$B24=$B23),Q23,Q23+1) -> 3 | R24: =IF($A24="","",IFERROR(INDEX(R$5:R23,MATCH($A24,$A$5:$A23,0)),MAX(R$5:R23)+1)) -> 1
A25: Datos del sistema (oculto) | B25: Dirección y notificación | C25: Descripción Distrito | D25: Dato oculto | G25: Sí | H25: No | J25: datosFormulario.personas[0].direccion.descripcionDistrito | K25: =IF(J25="","",IFERROR(INDEX('JSON del cliente'!$B$5:$B$288,MATCH(J25,'JSON del cliente'!$A$5:$A$288,0)),"no está en el JSON")) -> San Juan | M25: Se calcula | N25: Sí | Q25: =IF(AND($A25=$A24,$B25=$B24),Q24,Q24+1) -> 3 | R25: =IF($A25="","",IFERROR(INDEX(R$5:R24,MATCH($A25,$A$5:$A24,0)),MAX(R$5:R24)+1)) -> 1
A26: Datos Generales | B26: Información de la Solicitud | C26: Lugar | D26: Texto corto | F26: Sí | G26: No | H26: Sí | J26: datosFormulario.datosGenerales.lugar | K26: =IF(J26="","",IFERROR(INDEX('JSON del cliente'!$B$5:$B$288,MATCH(J26,'JSON del cliente'!$A$5:$A$288,0)),"no está en el JSON")) -> San José | M26: máx. 50 | N26: Sí | Q26: =IF(AND($A26=$A25,$B26=$B25),Q25,Q25+1) -> 4 | R26: =IF($A26="","",IFERROR(INDEX(R$5:R25,MATCH($A26,$A$5:$A25,0)),MAX(R$5:R25)+1)) -> 2
A27: Datos Generales | B27: Información de la Solicitud | C27: Fecha | D27: Fecha | F27: Sí | G27: Sí | H27: Sí | J27: datosFormulario.datosGenerales.fechaCreacion | K27: =IF(J27="","",IFERROR(INDEX('JSON del cliente'!$B$5:$B$288,MATCH(J27,'JSON del cliente'!$A$5:$A$288,0)),"no está en el JSON")) -> 2026-08-01 | L27: día / mes / año | N27: Sí | O27: Se completa con la fecha del día | Q27: =IF(AND($A27=$A26,$B27=$B26),Q26,Q26+1) -> 4 | R27: =IF($A27="","",IFERROR(INDEX(R$5:R26,MATCH($A27,$A$5:$A26,0)),MAX(R$5:R26)+1)) -> 2
A28: Información de Póliza | B28: Datos del Asesor | C28: Código de intermediario | D28: Número | F28: Sí | G28: Sí | H28: No | J28: datosFormulario.datosGenerales.intermediario.codigoIntermediario | K28: =IF(J28="","",IFERROR(INDEX('JSON del cliente'!$B$5:$B$288,MATCH(J28,'JSON del cliente'!$A$5:$A$288,0)),"no está en el JSON")) -> 1100340 | M28: 6 dígitos | N28: Sí | Q28: =IF(AND($A28=$A27,$B28=$B27),Q27,Q27+1) -> 5 | R28: =IF($A28="","",IFERROR(INDEX(R$5:R27,MATCH($A28,$A$5:$A27,0)),MAX(R$5:R27)+1)) -> 3
A29: Información de Póliza | B29: Datos del Asesor | C29: Nombre del asesor | D29: Texto corto | F29: Sí | G29: Sí | H29: No | J29: datosFormulario.datosGenerales.intermediario.nombre | K29: =IF(J29="","",IFERROR(INDEX('JSON del cliente'!$B$5:$B$288,MATCH(J29,'JSON del cliente'!$A$5:$A$288,0)),"no está en el JSON")) -> Geonanny Ulloa Soto | N29: Sí | Q29: =IF(AND($A29=$A28,$B29=$B28),Q28,Q28+1) -> 5 | R29: =IF($A29="","",IFERROR(INDEX(R$5:R28,MATCH($A29,$A$5:$A28,0)),MAX(R$5:R28)+1)) -> 3
A30: Información de Póliza | B30: Datos de la Póliza | C30: Número de póliza madre | D30: Texto corto | F30: Sí | G30: Sí | H30: No | J30: datosFormulario.datosGenerales.polizaMadre.numeroPoliza | K30: =IF(J30="","",IFERROR(INDEX('JSON del cliente'!$B$5:$B$288,MATCH(J30,'JSON del cliente'!$A$5:$A$288,0)),"no está en el JSON")) -> 0220EQE000123402 | M30: 16 caracteres | N30: Sí | Q30: =IF(AND($A30=$A29,$B30=$B29),Q29,Q29+1) -> 6 | R30: =IF($A30="","",IFERROR(INDEX(R$5:R29,MATCH($A30,$A$5:$A29,0)),MAX(R$5:R29)+1)) -> 3
A31: Información de Póliza | B31: Datos de la Póliza | C31: Vigencia desde | D31: Fecha | F31: Sí | G31: Sí | H31: No | J31: datosFormulario.datosGenerales.polizaMadre.vigenciaDesde | K31: =IF(J31="","",IFERROR(INDEX('JSON del cliente'!$B$5:$B$288,MATCH(J31,'JSON del cliente'!$A$5:$A$288,0)),"no está en el JSON")) -> 2026-01-01 | N31: Sí | Q31: =IF(AND($A31=$A30,$B31=$B30),Q30,Q30+1) -> 6 | R31: =IF($A31="","",IFERROR(INDEX(R$5:R30,MATCH($A31,$A$5:$A30,0)),MAX(R$5:R30)+1)) -> 3
A32: Información de Póliza | B32: Datos de la Póliza | C32: Vigencia hasta | D32: Fecha | F32: Sí | G32: Sí | H32: No | J32: datosFormulario.datosGenerales.polizaMadre.vigenciaHasta | K32: =IF(J32="","",IFERROR(INDEX('JSON del cliente'!$B$5:$B$288,MATCH(J32,'JSON del cliente'!$A$5:$A$288,0)),"no está en el JSON")) -> 2027-01-01 | N32: Sí | Q32: =IF(AND($A32=$A31,$B32=$B31),Q31,Q31+1) -> 6 | R32: =IF($A32="","",IFERROR(INDEX(R$5:R31,MATCH($A32,$A$5:$A31,0)),MAX(R$5:R31)+1)) -> 3
A33: Información de Póliza | B33: Información adicional | C33: ¿Tiene pólizas con otra compañía aseguradora? | D33: Sí / No | F33: Sí | G33: No | H33: Sí | J33: datosFormulario.datosGenerales.datosAdicionales.indicadorOtraAseguradora | K33: =IF(J33="","",IFERROR(INDEX('JSON del cliente'!$B$5:$B$288,MATCH(J33,'JSON del cliente'!$A$5:$A$288,0)),"no está en el JSON")) -> Si | N33: Sí | Q33: =IF(AND($A33=$A32,$B33=$B32),Q32,Q32+1) -> 7 | R33: =IF($A33="","",IFERROR(INDEX(R$5:R32,MATCH($A33,$A$5:$A32,0)),MAX(R$5:R32)+1)) -> 3
A34: Información de Póliza | B34: Información adicional | C34: Nombre de la compañía aseguradora | D34: Texto corto | F34: Sí | G34: No | H34: Sí | I34: si ¿Tiene pólizas con otra compañía aseguradora? = Sí | J34: datosFormulario.datosGenerales.datosAdicionales.nombreOtraAseguradora | K34: =IF(J34="","",IFERROR(INDEX('JSON del cliente'!$B$5:$B$288,MATCH(J34,'JSON del cliente'!$A$5:$A$288,0)),"no está en el JSON")) -> Mapre S.A. | M34: máx. 50 | N34: Sí | Q34: =IF(AND($A34=$A33,$B34=$B33),Q33,Q33+1) -> 7 | R34: =IF($A34="","",IFERROR(INDEX(R$5:R33,MATCH($A34,$A$5:$A33,0)),MAX(R$5:R33)+1)) -> 3
A35: Datos del Asegurado | B35: Datos Asegurado | C35: Tipo de identificación | D35: Una opción de una lista | E35: Ver catálogo | F35: Sí | G35: Sí | H35: Sí | J35: datosFormulario.personas[0].codigoTipoIdentificacion | K35: =IF(J35="","",IFERROR(INDEX('JSON del cliente'!$B$5:$B$288,MATCH(J35,'JSON del cliente'!$A$5:$A$288,0)),"no está en el JSON")) -> Física | N35: Sí | Q35: =IF(AND($A35=$A34,$B35=$B34),Q34,Q34+1) -> 8 | R35: =IF($A35="","",IFERROR(INDEX(R$5:R34,MATCH($A35,$A$5:$A34,0)),MAX(R$5:R34)+1)) -> 4
A36: Datos del Asegurado | B36: Datos Asegurado | C36: Número de identificación | D36: Texto corto | F36: Sí | G36: Sí | H36: Sí | J36: datosFormulario.personas[0].identificacion | K36: =IF(J36="","",IFERROR(INDEX('JSON del cliente'!$B$5:$B$288,MATCH(J36,'JSON del cliente'!$A$5:$A$288,0)),"no está en el JSON")) -> 1103330564 | M36: 9 dígitos si es Física | N36: Sí | Q36: =IF(AND($A36=$A35,$B36=$B35),Q35,Q35+1) -> 8 | R36: =IF($A36="","",IFERROR(INDEX(R$5:R35,MATCH($A36,$A$5:$A35,0)),MAX(R$5:R35)+1)) -> 4
A37: Datos del Asegurado | B37: Datos Asegurado | C37: Primer nombre | D37: Texto corto | F37: Sí | G37: Sí | H37: Sí | J37: datosFormulario.personas[0].primerNombre | K37: =IF(J37="","",IFERROR(INDEX('JSON del cliente'!$B$5:$B$288,MATCH(J37,'JSON del cliente'!$A$5:$A$288,0)),"no está en el JSON")) -> Alejandro | M37: máx. 50 | N37: Sí | Q37: =IF(AND($A37=$A36,$B37=$B36),Q36,Q36+1) -> 8 | R37: =IF($A37="","",IFERROR(INDEX(R$5:R36,MATCH($A37,$A$5:$A36,0)),MAX(R$5:R36)+1)) -> 4
A38: Datos del Asegurado | B38: Datos Asegurado | C38: Segundo nombre | D38: Texto corto | F38: No | G38: Sí | H38: Sí | J38: datosFormulario.personas[0].segundoNombre | K38: =IF(J38="","",IFERROR(INDEX('JSON del cliente'!$B$5:$B$288,MATCH(J38,'JSON del cliente'!$A$5:$A$288,0)),"no está en el JSON")) -> 0 | M38: máx. 50 | N38: Sí | Q38: =IF(AND($A38=$A37,$B38=$B37),Q37,Q37+1) -> 8 | R38: =IF($A38="","",IFERROR(INDEX(R$5:R37,MATCH($A38,$A$5:$A37,0)),MAX(R$5:R37)+1)) -> 4
A39: Datos del Asegurado | B39: Datos Asegurado | C39: Primer apellido | D39: Texto corto | F39: Sí | G39: Sí | H39: Sí | J39: datosFormulario.personas[0].primerApellido | K39: =IF(J39="","",IFERROR(INDEX('JSON del cliente'!$B$5:$B$288,MATCH(J39,'JSON del cliente'!$A$5:$A$288,0)),"no está en el JSON")) -> Ulloa | M39: máx. 50 | N39: Sí | Q39: =IF(AND($A39=$A38,$B39=$B38),Q38,Q38+1) -> 8 | R39: =IF($A39="","",IFERROR(INDEX(R$5:R38,MATCH($A39,$A$5:$A38,0)),MAX(R$5:R38)+1)) -> 4
A40: Datos del Asegurado | B40: Datos Asegurado | C40: Segundo apellido | D40: Texto corto | F40: No | G40: Sí | H40: Sí | J40: datosFormulario.personas[0].segundoApellido | K40: =IF(J40="","",IFERROR(INDEX('JSON del cliente'!$B$5:$B$288,MATCH(J40,'JSON del cliente'!$A$5:$A$288,0)),"no está en el JSON")) -> Pérez | M40: máx. 50 | N40: Sí | Q40: =IF(AND($A40=$A39,$B40=$B39),Q39,Q39+1) -> 8 | R40: =IF($A40="","",IFERROR(INDEX(R$5:R39,MATCH($A40,$A$5:$A39,0)),MAX(R$5:R39)+1)) -> 4
A41: Datos del Asegurado | B41: Datos Asegurado | C41: Fecha de nacimiento | D41: Fecha | F41: Sí | G41: Sí | H41: Sí | J41: datosFormulario.personas[0].fechaNacimiento | K41: =IF(J41="","",IFERROR(INDEX('JSON del cliente'!$B$5:$B$288,MATCH(J41,'JSON del cliente'!$A$5:$A$288,0)),"no está en el JSON")) -> 1979-04-26 | N41: Sí | O41: Una sola pregunta; en el PDF la reparte la herramienta | Q41: =IF(AND($A41=$A40,$B41=$B40),Q40,Q40+1) -> 8 | R41: =IF($A41="","",IFERROR(INDEX(R$5:R40,MATCH($A41,$A$5:$A40,0)),MAX(R$5:R40)+1)) -> 4
...

Sheet JSON del cliente
A1: Lo que trae tu JSON
A2: Se arma solo a partir del JSON que cargaste. No hace falta editar esta hoja.
A3: "¿Se usa?" dice si alguna pregunta ya tomó esa ruta. Las que quedan en No, Namirial las revisa y las suma a los datos ocultos si corresponde.
A4: Ruta JSON | B4: Valor de ejemplo | C4: ¿Se usa?
A5: encabezado.codigoTipoFormulario | B5: EQE02 | C5: =IF(COUNTIF(Preguntas!$J$6:$J$360,A5)>0,"Sí","No") -> Sí
A6: encabezado.descripcionTipoFormulario | B6: Equipo Electrónico Modalidad Adhesión para Equipo Móvil y/o Portátil | C6: =IF(COUNTIF(Preguntas!$J$6:$J$360,A6)>0,"Sí","No") -> Sí
A7: encabezado.codigoTipoTramite | B7: Ver catálogo | C7: =IF(COUNTIF(Preguntas!$J$6:$J$360,A7)>0,"Sí","No") -> Sí
A8: encabezado.descripcionTipoTramite | B8: Ver catálogo | C8: =IF(COUNTIF(Preguntas!$J$6:$J$360,A8)>0,"Sí","No") -> Sí
A9: encabezado.identificadorTransaccionInterno | B9: INS_SG_P14_EQE02_I_20260801_A_3_0031018555690 | C9: =IF(COUNTIF(Preguntas!$J$6:$J$360,A9)>0,"Sí","No") -> Sí
A10: encabezado.correoElectronico | B10: aleulloaperez@gmail.com | C10: =IF(COUNTIF(Preguntas!$J$6:$J$360,A10)>0,"Sí","No") -> Sí
A11: encabezado.codigoProducto | B11: 155 | C11: =IF(COUNTIF(Preguntas!$J$6:$J$360,A11)>0,"Sí","No") -> Sí
A12: encabezado.descripcionProducto | B12: Equipo Electrónico Riesgo Nombrado Equipo Movil y/o Portátil | C12: =IF(COUNTIF(Preguntas!$J$6:$J$360,A12)>0,"Sí","No") -> Sí
A13: encabezado.nombreCompletoCliente | B13: Alejandro Ulloa Pérez | C13: =IF(COUNTIF(Preguntas!$J$6:$J$360,A13)>0,"Sí","No") -> Sí
A14: encabezado.identificadorArchivo | B14: idNamirial | C14: =IF(COUNTIF(Preguntas!$J$6:$J$360,A14)>0,"Sí","No") -> Sí
A15: datosFormulario.datosGenerales.lugar | B15: San José | C15: =IF(COUNTIF(Preguntas!$J$6:$J$360,A15)>0,"Sí","No") -> Sí
A16: datosFormulario.datosGenerales.fechaCreacion | B16: 2026-08-01 | C16: =IF(COUNTIF(Preguntas!$J$6:$J$360,A16)>0,"Sí","No") -> Sí
A17: datosFormulario.datosGenerales.indicadorClienteDaConsentimiento | C17: =IF(COUNTIF(Preguntas!$J$6:$J$360,A17)>0,"Sí","No") -> Sí
A18: datosFormulario.datosGenerales.indicadorAceptaTerminos | C18: =IF(COUNTIF(Preguntas!$J$6:$J$360,A18)>0,"Sí","No") -> Sí
A19: datosFormulario.datosGenerales.intermediario.codigoIntermediario | B19: 1100340 | C19: =IF(COUNTIF(Preguntas!$J$6:$J$360,A19)>0,"Sí","No") -> Sí
A20: datosFormulario.datosGenerales.intermediario.identificacion | B20: 110330564 | C20: =IF(COUNTIF(Preguntas!$J$6:$J$360,A20)>0,"Sí","No") -> No
A21: datosFormulario.datosGenerales.intermediario.codigoTipoIdentificacion | B21: Física Nacional | C21: =IF(COUNTIF(Preguntas!$J$6:$J$360,A21)>0,"Sí","No") -> No
A22: datosFormulario.datosGenerales.intermediario.nombre | B22: Geonanny Ulloa Soto | C22: =IF(COUNTIF(Preguntas!$J$6:$J$360,A22)>0,"Sí","No") -> Sí
A23: datosFormulario.datosGenerales.intermediario.correoElectronico | B23: gulloasoto@gmail.com | C23: =IF(COUNTIF(Preguntas!$J$6:$J$360,A23)>0,"Sí","No") -> No
A24: datosFormulario.datosGenerales.polizaMadre.numeroPoliza | B24: 0220EQE000123402 | C24: =IF(COUNTIF(Preguntas!$J$6:$J$360,A24)>0,"Sí","No") -> Sí
A25: datosFormulario.datosGenerales.polizaMadre.vigenciaDesde | B25: 2026-01-01 | C25: =IF(COUNTIF(Preguntas!$J$6:$J$360,A25)>0,"Sí","No") -> Sí
A26: datosFormulario.datosGenerales.polizaMadre.vigenciaHasta | B26: 2027-01-01 | C26: =IF(COUNTIF(Preguntas!$J$6:$J$360,A26)>0,"Sí","No") -> Sí
A27: datosFormulario.datosGenerales.polizaMadre.codigoTipoIdentificacionTomador | B27: Jurídica Nacional | C27: =IF(COUNTIF(Preguntas!$J$6:$J$360,A27)>0,"Sí","No") -> No
A28: datosFormulario.datosGenerales.polizaMadre.identificacionTomador | B28: 10 caracteres númericos | C28: =IF(COUNTIF(Preguntas!$J$6:$J$360,A28)>0,"Sí","No") -> No
A29: datosFormulario.datosGenerales.polizaMadre.nombreTomador | B29: 50 caracteres alfanuméricos | C29: =IF(COUNTIF(Preguntas!$J$6:$J$360,A29)>0,"Sí","No") -> No
A30: datosFormulario.datosGenerales.polizaMadre.codigoMoneda | B30: Colones | C30: =IF(COUNTIF(Preguntas!$J$6:$J$360,A30)>0,"Sí","No") -> No
... A38: datosFormulario.datosGenerales.datosAdicionales.nombreOtraAseguradora | B38: Mapre S.A. | C38: =IF(COUNTIF(Preguntas!$J$6:$J$360,A38)>0,"Sí","No") -> Sí
A39: datosFormulario.datosGenerales.datosAdicionales.polizaOtraAseguradora | C39: =IF(COUNTIF(Preguntas!$J$6:$J$360,A39)>0,"Sí","No") -> No
A40: datosFormulario.personas[0].codigoTipo | B40: ASG | C40: =IF(COUNTIF(Preguntas!$J$6:$J$360,A40)>0,"Sí","No") -> Sí
A41: datosFormulario.personas[0].descripcionTipo | B41: Asegurado | C41: =IF(COUNTIF(Preguntas!$J$6:$J$360,A41)>0,"Sí","No") -> Sí
A42: datosFormulario.personas[0].codigoTipoIdentificacion | B42: Física | C42: =IF(COUNTIF(Preguntas!$J$6:$J$360,A42)>0,"Sí","No") -> Sí
A43: datosFormulario.personas[0].descripcionTipoIdentificacion | B43: Física | C43: =IF(COUNTIF(Preguntas!$J$6:$J$360,A43)>0,"Sí","No") -> Sí
A44: datosFormulario.personas[0].identificacion | B44: 1103330564 | C44: =IF(COUNTIF(Preguntas!$J$6:$J$360,A44)>0,"Sí","No") -> Sí
A45: datosFormulario.personas[0].correoElectronico | B45: aulloap@grupoins.com | C45: =IF(COUNTIF(Preguntas!$J$6:$J$360,A45)>0,"Sí","No") -> Sí
A46: datosFormulario.personas[0].nombreCompleto | B46: Alejandro Ulloa Pérez | C46: =IF(COUNTIF(Preguntas!$J$6:$J$360,A46)>0,"Sí","No") -> Sí
A47: datosFormulario.personas[0].primerApellido | B47: Ulloa | C47: =IF(COUNTIF(Preguntas!$J$6:$J$360,A47)>0,"Sí","No") -> Sí
...

Sheet Cómo se completa
A1: Columna | B1: Qué poner | C1: En el machote del INS
A2: Sección | B2: La pantalla del formulario. Elegila de la lista; se puede escribir una nueva. | C2: Pasos Formulario
A3: Subsección | B3: El bloque dentro de la pantalla. La lista muestra solo las de la sección elegida. | C3: Sección
A4: Pregunta | B4: Cómo la ve la persona. | C4: Nombre del campo en formulario
A5: Tipo | B5: De la lista. Una fecha es una sola pregunta de tipo Fecha. | C5: Tipo de dato
A6: Opciones | B6: Para listas: opción=código separadas por punto y coma. Ej.: Masculino=M; Femenino=F. O "Ver catálogo". | C6: Valor (una fila por opción)
A7: Obligatoria | B7: Sí / No. | C7: Obligatorio (Both / WEB / JSON / None)
A8: Viene prellenado / Se puede editar | B8: Sí / No en cada una. | C8: Visualización (Disabled / Dato Prellenado / editable)
A9: Se muestra si | B9: Si depende de otra respuesta. Ej.: si ¿Tiene pólizas con otra compañía aseguradora? = Sí | C9: Regla
A10: Ruta JSON | B10: De la lista: sale de tu JSON. [i] = se repite (ej. bienes). | C10: Nombre de la sección del JSON
A11: Valor en el JSON | B11: Se completa solo. Si dice "no está en el JSON", revisá la ruta.
A12: En el PDF va partido en | B12: Solo si en el PDF va en varios casilleros. Ej.: día / mes / año. | C12: Nombre en PDF
A13: Reglas / formato | B13: Ej.: 9 dígitos · máx. 50 · email. | C13: Regla
A14: ¿Va? | B14: No = se saca del formulario.
A15: ID (no tocar) | B15: Lo usa la herramienta para no perder lo ya conectado. En filas nuevas, dejalo vacío.
A16: Filas grises | B16: Datos ocultos (Datos del sistema). Los completa Namirial. | C16: Pasos / Sección = JSON

Sheet Listas
A1: Sección | B1: Subsección | D1: Secciones (únicas)
A2: Datos del sistema (oculto) | B2: Encabezado | D2: Datos del sistema (oculto)
A3: Datos del sistema (oculto) | B3: Personas | D3: Datos Generales
A4: Datos del sistema (oculto) | B4: Dirección y notificación | D4: Información de Póliza
A5: Datos Generales | B5: Información de la Solicitud | D5: Datos del Tomador
A6: Información de Póliza | B6: Datos del Asesor | D6: Datos del Asegurado
A7: Información de Póliza | B7: Datos de la Póliza | D7: Datos del Dependiente
A8: Información de Póliza | B8: Información adicional | D8: Datos del Beneficiario
A9: Datos del Tomador | B9: Datos Tomador | D9: Información del riesgo
A10: Datos del Tomador | B10: Contacto y ubicación | D10: Declaraciones y Autorización
A11: Datos del Asegurado | B11: Datos Asegurado
A12: Datos del Asegurado | B12: Contacto y ubicación
A13: Datos del Asegurado | B13: Preferencias de notificación
A14: Datos del Dependiente | B14: Datos Dependiente
A15: Datos del Dependiente | B15: Contacto y ubicación
A16: Datos del Beneficiario | B16: Datos Beneficiario
A17: Datos del Beneficiario | B17: Contacto y ubicación
A18: Información del riesgo | B18: Información del riesgo
A19: Información del riesgo | B19: Bienes por asegurar
A20: Información del riesgo | B20: Coberturas Básicas
A21: Información del riesgo | B21: Coberturas Adicionales
A22: Declaraciones y Autorización | B22: Autorizaciones
A23: Declaraciones y Autorización | B23: Declaraciones Legales
